Workbook

Sheet ĐNTT
A1: CÔNG TY CỔ PHẦN TẬP ĐOÀN THIẾT BỊ XÂY DỰNG TP | D1: CỘNG HOÀ XÃ HỘI CHỦ NGHĨA VIỆT NAM
D2: Độc lập - Tự do - Hạnh phúc
G4: Hà Nội, ngày …. tháng …. năm 2025
A6: GIẤY ĐỀ NGHỊ THANH TOÁN
A8: Kính gửi: CÔNG TY TNHH XÂY DỰNG VIỆT PANEL
A9: Công ty Cổ phần Tập đoàn Thiết bị xây dựng TP xin gửi tới Quý Công ty lời chào trân trọng và hợp tác.
A10: =+ĐCCN!$A$7 -> - Căn cứ Hợp đồng kinh tế số 0412/HĐKT2025/TP-VIETPANEL ký ngày 04/12/2025 giữa Công ty TNHH xây dựng Việt Panel và Công ty Cổ phần Tập đoàn Thiết bị xây dựng TP về việc cho thuê thiết bị xây dựng.
A11: - Căn cứ Biên bản đối chiếu giá trị thuê thiết bị tháng 12/2025;
B12: - Giá trị đề nghị thanh toán: | E12: =ĐCCN!G28 -> 30768025 | F12: đồng.
A13: =ĐCCN!A29 -> Bằng chữ: | B13: =ĐCCN!B29 -> Ba mươi triệu, bảy trăm sáu mươi tám nghìn, không trăm hai mươi lăm đồng./.
A14: Công ty Cổ phần Tập đoàn Thiết bị xây dựng TP kính đề nghị Quý công ty thanh toán số tiền trên cho chúng tôi theo thông tin dưới đây:
B15: - Đơn vị thụ hưởng: | D15: Công ty Cổ phần Tập đoàn Thiết bị Xây dựng TP
B16: - Địa chỉ: | D16: Thôn Trung, Xã Ô Diên, Thành phố Hà Nội
B17: - Tài khoản số: | D17: 8331100096008, tại Ngân hàng Thương mại cổ phần Quân đội - Chi nhánh Hoàng Quốc Việt
A18: Xin trân trọng cảm ơn!
E19: CÔNG TY CỔ PHẦN TẬP ĐOÀN THIẾT BỊ XÂY DỰNG TP
A24: CÔNG TY CỔ PHẦN TẬP ĐOÀN THIẾT BỊ XÂY DỰNG TP | D24: CỘNG HOÀ XÃ HỘI CHỦ NGHĨA VIỆT NAM
D25: Độc lập - Tự do - Hạnh phúc
G27: Hà Nội, ngày …. tháng …. năm 2026
A29: GIẤY ĐỀ NGHỊ THANH TOÁN
A31: Kính gửi: CÔNG TY TNHH XÂY DỰNG VIỆT PANEL
A32: Công ty Cổ phần Tập đoàn Thiết bị xây dựng TP xin gửi tới Quý Công ty lời chào trân trọng và hợp tác.
A33: =+ĐCCN!$A$7 -> - Căn cứ Hợp đồng kinh tế số 0412/HĐKT2025/TP-VIETPANEL ký ngày 04/12/2025 giữa Công ty TNHH xây dựng Việt Panel và Công ty Cổ phần Tập đoàn Thiết bị xây dựng TP về việc cho thuê thiết bị xây dựng.
A34: - Căn cứ Biên bản đối chiếu giá trị thuê thiết bị tháng 01/2026;
B35: - Giá trị đề nghị thanh toán trong kỳ: | E35: ='Giá trị'!J296 -> 884490707 | F35: đồng.
A36: =$A$13 -> Bằng chữ: | B36: ='Giá trị'!B297 -> Tám trăm tám mươi tư triệu, bốn trăm chín mươi nghìn, bảy trăm linh bảy đồng./.
A37: Công ty Cổ phần Tập đoàn Thiết bị xây dựng TP kính đề nghị Quý công ty thanh toán số tiền trên cho chúng tôi theo thông tin dưới đây:
B38: - Đơn vị thụ hưởng: | D38: Công ty Cổ phần Tập đoàn Thiết bị Xây dựng TP
B39: - Địa chỉ: | D39: Thôn Trung, Xã Ô Diên, Thành phố Hà Nội
B40: - Tài khoản số: | D40: 8331100096008, tại Ngân hàng Thương mại cổ phần Quân đội - Chi nhánh Hoàng Quốc Việt
A41: Xin trân trọng cảm ơn!
E42: CÔNG TY CỔ PHẦN TẬP ĐOÀN THIẾT BỊ XÂY DỰNG TP
A47: CÔNG TY CỔ PHẦN TẬP ĐOÀN THIẾT BỊ XÂY DỰNG TP | D47: CỘNG HOÀ XÃ HỘI CHỦ NGHĨA VIỆT NAM
D48: Độc lập - Tự do - Hạnh phúc
G50: Hà Nội, ngày …. tháng …. năm 2026
A52: GIẤY ĐỀ NGHỊ THANH TOÁN
A54: Kính gửi: CÔNG TY TNHH XÂY DỰNG VIỆT PANEL
A55: Công ty Cổ phần Tập đoàn Thiết bị xây dựng TP xin gửi tới Quý Công ty lời chào trân trọng và hợp tác.
A56: =+ĐCCN!$A$7 -> - Căn cứ Hợp đồng kinh tế số 0412/HĐKT2025/TP-VIETPANEL ký ngày 04/12/2025 giữa Công ty TNHH xây dựng Việt Panel và Công ty Cổ phần Tập đoàn Thiết bị xây dựng TP về việc cho thuê thiết bị xây dựng.
A57: - Căn cứ Biên bản đối chiếu giá trị thuê thiết bị tháng 02/2026;
...

Sheet ĐCCN
A1: CỘNG HÒA XÃ HỘI CHỦ NGHĨA VIỆT NAM
A2: Độc lập - Tự do - Hạnh phúc
A4: BIÊN BẢN ĐỐI CHIẾU CÔNG NỢ
A5: Tháng 11/2025
A7: - Căn cứ Hợp đồng kinh tế số 0412/HĐKT2025/TP-VIETPANEL ký ngày 04/12/2025 giữa Công ty TNHH xây dựng Việt Panel và Công ty Cổ phần Tập đoàn Thiết bị xây dựng TP về việc cho thuê thiết bị xây dựng.
A8: BÊN THUÊ (BÊN A): CÔNG TY TNHH XÂY DỰNG VIỆT PANEL
A9: Địa chỉ: | C9: Thôn Đông Phù, Xã Tiên Du, Tỉnh Bắc Ninh, Việt Nam
A10: Điện thoại: | C10: 0222 6535 699
A11: Tài khoản ngân hàng số: | C11: 616139999 | E11: Tại MB Ngân hàng quân đội
A12: Mã số thuế: | C12: 2300856941
A13: Người đại diện: | C13: Ông Lưu Đình Cải | E13: Chức vụ: Giám đốc
A15: BÊN CHO THUÊ (BÊN B): CÔNG TY CỔ PHẦN TẬP ĐOÀN THIẾT BỊ XÂY DỰNG TP
A16: Địa chỉ: | C16: Thôn Trung, xã Ô Diên, Thành phố Hà Nội, Việt Nam
A17: Điện thoại: | C17: 02433250143
A18: Tài khoản ngân hàng số: | C18: 8331100096008 | E18: Tại Ngân hàng Thương mại cổ phần Quân đội - Chi nhánh Hoàng Quốc Việt
A19: Mã số thuế: | C19: 0105204346
A20: Người đại diện: | C20: Ông Hữu Minh Tiến | E20: Chức vụ: Phó Tổng giám đốc
A22: Hai bên cùng nhau đối chiếu công nợ tiền thuê thiết bị dự án Senci, KCN Phúc Điền, Hải Dương như sau:
A23: STT | B23: Nội dung | G23: Giá trị (vnđ)
A24: 1 | B24: Giá trị bên A đã tạm ứng cho bên B | G24: 1255054014
A25: 2 | B25: Giá trị bên A nợ bên B đầu kỳ
A26: 3 | B26: Giá trị tiền thuê phát sinh tháng 12/2025 | G26: ='Giá trị'!J105 -> 30768025
A27: 4 | B27: Giá trị bên A thanh toán cho bên B trong kỳ | G27: 0
A28: 5 | B28: Giá trị bên A nợ bên B cuối kỳ | G28: =G25+G26-G27 -> 30768025
A29: Bằng chữ: | B29: ='Giá trị'!B106 -> Ba mươi triệu, bảy trăm sáu mươi tám nghìn, không trăm hai mươi lăm đồng./.
A31: ĐẠI DIỆN BÊN THUÊ | E31: ĐẠI DIỆN BÊN CHO THUÊ
A34: CỘNG HÒA XÃ HỘI CHỦ NGHĨA VIỆT NAM
A35: Độc lập - Tự do - Hạnh phúc
A37: BIÊN BẢN ĐỐI CHIẾU CÔNG NỢ
A38: Tháng 01/2026
A40: - Căn cứ Hợp đồng kinh tế số 0412/HĐKT2025/TP-VIETPANEL ký ngày 04/12/2025 giữa Công ty TNHH xây dựng Việt Panel và Công ty Cổ phần Tập đoàn Thiết bị xây dựng TP về việc cho thuê thiết bị xây dựng.
A41: BÊN THUÊ (BÊN A): CÔNG TY TNHH XÂY DỰNG VIỆT PANEL
A42: Địa chỉ: | C42: Thôn Đông Phù, Xã Tiên Du, Tỉnh Bắc Ninh, Việt Nam
A43: Điện thoại: | C43: 0222 6535 699
A44: Tài khoản ngân hàng số: | C44: 616139999 | E44: Tại MB Ngân hàng quân đội
A45: Mã số thuế: | C45: 2300856941
A46: Người đại diện: | C46: Ông Lưu Đình Cải | E46: Chức vụ: Giám đốc
A48: BÊN CHO THUÊ (BÊN B): CÔNG TY CỔ PHẦN TẬP ĐOÀN THIẾT BỊ XÂY DỰNG TP
A49: Địa chỉ: | C49: Thôn Trung, xã Ô Diên, Thành phố Hà Nội, Việt Nam
A50: Điện thoại: | C50: 02433250143
...

Sheet Giá trị
A1: CỘNG HÒA XÃ HỘI CHỦ NGHĨA VIỆT NAM
A2: Độc lập - Tự do - Hạnh phúc
A4: BIÊN BẢN ĐỐI CHIẾU GIÁ TRỊ THUÊ THIẾT BỊ
A5: =+"Tháng "&MONTH(L6)&"/2025" -> Tháng 12/2025 | L5: 45992
L6: 46022
A7: =ĐCCN!$A$7 -> - Căn cứ Hợp đồng kinh tế số 0412/HĐKT2025/TP-VIETPANEL ký ngày 04/12/2025 giữa Công ty TNHH xây dựng Việt Panel và Công ty Cổ phần Tập đoàn Thiết bị xây dựng TP về việc cho thuê thiết bị xây dựng.
A8: - Dự án: | B8: Senci
A9: - Địa chỉ: | B9: KCN Phúc Điền, Hải Dương
A10: - Căn cứ Biên bản đối chiếu khối lượng thuê thiết bị tháng 12/2025
A11: Hôm nay, ngày ……tháng……năm 2025, chúng tôi gồm:
A12: =ĐCCN!A8 -> BÊN THUÊ (BÊN A): CÔNG TY TNHH XÂY DỰNG VIỆT PANEL
A13: Địa chỉ: | B13: =ĐCCN!$C$9 -> Thôn Đông Phù, Xã Tiên Du, Tỉnh Bắc Ninh, Việt Nam
A14: Điện thoại: | C14: =ĐCCN!$C$10 -> 0222 6535 699
A15: Tài khoản ngân hàng số: | C15: =ĐCCN!$C$11 -> 616139999 | E15: =ĐCCN!$E$11 -> Tại MB Ngân hàng quân đội
A16: Mã số thuế: | C16: =ĐCCN!$C$12 -> 2300856941
A17: Người đại diện: | C17: =ĐCCN!$C$13 -> Ông Lưu Đình Cải | E17: =ĐCCN!$E$13 -> Chức vụ: Giám đốc
A19: BÊN CHO THUÊ (BÊN B): CÔNG TY CỔ PHẦN TẬP ĐOÀN THIẾT BỊ XÂY DỰNG TP
A20: Địa chỉ: Thôn Trung, xã Ô Diên, Thành phố Hà Nội, Việt Nam
A21: Điện thoại: | C21: 02433250143
A22: Tài khoản ngân hàng số: | C22: =ĐCCN!C18 -> 8331100096008 | E22: =ĐCCN!E18 -> Tại Ngân hàng Thương mại cổ phần Quân đội - Chi nhánh Hoàng Quốc Việt
A23: Mã số thuế: | C23: 0105204346
A24: Người đại diện: | C24: Ông Hữu Minh Tiến | E24: Chức vụ: Phó Tổng giám đốc
A26: Hai bên đối chiếu xác nhận giá trị thuê thiết bị từ ngày 20/12/2025 đến ngày 25/12/2025 như sau:
A28: STT | B28: Tên thiết bị | C28: Đơn vị tính | D28: Ngày nhận/trả trên phiếu | E28: Ngày tính thời gian | F28: Số lượng tồn đầu kỳ | G28: Số lượng phát sinh trong kỳ nhận (+) trả (-) | H28: Thời gian thuê | I28: Đơn giá thuê (vnđ/cái) | J28: Thành tiền thuê | K28: Ghi chú
A29: =ROMAN(1,0) -> I | B29: Thiết bị vật tư | J29: =SUBTOTAL(9,J30:J99) -> 28488912 | M29: =+J33+J37+J40+J52+J59+J66+J83 -> 25198912
A30: 1 | B30: Giáo ringlock 1.0m Kẽm | C30: Cây | D30: 46015 | E30: 46016 | G30: 1300 | H30: =E30-D30+1 -> 2 | I30: 85 | J30: =+I30*H30*G30 -> 221000 | K30: 46015
B31: Giáo ringlock 1.0m Kẽm | C31: Cây | D31: 46016 | E31: 46016 | G31: 1600 | H31: =E31-D31+1 -> 1 | I31: 85 | J31: =+I31*H31*G31 -> 136000 | K31: 46016
B32: Giáo ringlock 1.0m Kẽm | C32: Cây | D32: 46016 | E32: 46016 | G32: 1600 | H32: =E32-D32+1 -> 1 | I32: 85 | J32: =+I32*H32*G32 -> 136000 | K32: 46016
B33: Cộng | G33: =SUM(G30:G32) -> 4500 | J33: =+SUBTOTAL(109,J30:J32) -> 493000
A34: 2 | B34: Giáo ringlock 1.5m Kẽm | C34: Cây | D34: 46011 | E34: 46016 | G34: 700 | H34: =E34-D34+1 -> 6 | I34: 125 | J34: =+I34*H34*G34 -> 525000 | K34: 46011
B35: Giáo ringlock 1.5m Kẽm | C35: Cây | D35: 46016 | E35: 46016 | G35: 1600 | H35: =E35-D35+1 -> 1 | I35: 125 | J35: =+I35*H35*G35 -> 200000 | K35: 46016
B36: Giáo ringlock 1.5m Kẽm | C36: Cây | D36: 46016 | E36: 46016 | G36: 1600 | H36: =E36-D36+1 -> 1 | I36: 125 | J36: =+I36*H36*G36 -> 200000 | K36: 46016
B37: Cộng | G37: =SUM(G34:G36) -> 3900 | J37: =+SUBTOTAL(109,J34:J36) -> 925000
A38: 3 | B38: Giáo ringlock 2.0m Kẽm | C38: Cây | D38: 46011 | E38: 46016 | G38: 700 | H38: =E38-D38+1 -> 6 | I38: 159 | J38: =+I38*H38*G38 -> 667800 | K38: 46011 | L38: Giằng chéo ringlock 1610mm
B39: Giáo ringlock 2.0m Kẽm | C39: Cây | D39: 46015 | E39: 46016 | G39: 400 | H39: =E39-D39+1 -> 2 | I39: 159 | J39: =+I39*H39*G39 -> 127200 | K39: 46015
B40: Cộng | G40: =SUM(G38:G39) -> 1100 | J40: =+SUBTOTAL(109,J38:J39) -> 795000
A41: 4 | B41: Giáo ringlock 2.5m Kẽm | C41: Cây | D41: 46012 | E41: 46016 | G41: 1000 | H41: =E41-D41+1 -> 5 | I41: 185 | J41: =+I41*H41*G41 -> 925000 | K41: 46012 | L41: Giằng chéo ringlock 1870mm
B42: Giáo ringlock 2.5m Kẽm | C42: Cây | D42: 46013 | E42: 46016 | G42: 2200 | H42: =E42-D42+1 -> 4 | I42: 185 | J42: =+I42*H42*G42 -> 1628000 | K42: 46013
B43: Giáo ringlock 2.5m Kẽm | C43: Cây | D43: 46013 | E43: 46016 | G43: 1100 | H43: =E43-D43+1 -> 4 | I43: 185 | J43: =+I43*H43*G43 -> 814000 | K43: 46013
B44: Giáo ringlock 2.5m Kẽm | C44: Cây | D44: 46013 | E44: 46016 | G44: 2200 | H44: =E44-D44+1 -> 4 | I44: 185 | J44: =+I44*H44*G44 -> 1628000 | K44: 46013
...

Sheet Khối lượng
A1: CỘNG HÒA XÃ HỘI CHỦ NGHĨA VIỆT NAM
A2: Độc lập - Tự do - Hạnh phúc
A4: BIÊN BẢN ĐỐI CHIẾU KHỐI LƯỢNG THUÊ THIẾT BỊ
A5: Tháng 12/2025
A7: ='Giá trị'!$A$7:$K$7 -> - Căn cứ Hợp đồng kinh tế số 0412/HĐKT2025/TP-VIETPANEL ký ngày 04/12/2025 giữa Công ty TNHH xây dựng Việt Panel và Công ty Cổ phần Tập đoàn Thiết bị xây dựng TP về việc cho thuê thiết bị xây dựng.
A8: - Dự án: | B8: ='Giá trị'!$B$8 -> Senci
A9: - Địa chỉ: | B9: ='Giá trị'!$B$9 -> KCN Phúc Điền, Hải Dương
A10: - Căn cứ tình hình giao nhận thực tế giữa 02 bên.
A11: Hôm nay, ngày ……tháng……năm 2025, chúng tôi gồm:
A12: ='Giá trị'!$A$12 -> BÊN THUÊ (BÊN A): CÔNG TY TNHH XÂY DỰNG VIỆT PANEL
A13: ='Giá trị'!A13 -> Địa chỉ: | B13: ='Giá trị'!$B$13 -> Thôn Đông Phù, Xã Tiên Du, Tỉnh Bắc Ninh, Việt Nam
A14: Điện thoại: | C14: ='Giá trị'!$C$14:$D$14 -> 0222 6535 699
A15: Tài khoản ngân hàng số: | C15: ='Giá trị'!$C$15:$D$15 -> 616139999 | E15: ='Giá trị'!$E$15 -> Tại MB Ngân hàng quân đội
A16: Mã số thuế: | C16: ='Giá trị'!$C$16:$D$16 -> 2300856941
A17: Người đại diện: | C17: ='Giá trị'!$C$17 -> Ông Lưu Đình Cải | E17: ='Giá trị'!$E$17 -> Chức vụ: Giám đốc
A19: BÊN CHO THUÊ (BÊN B): CÔNG TY CỔ PHẦN TẬP ĐOÀN THIẾT BỊ XÂY DỰNG TP
A20: Địa chỉ: Thôn Trung, xã Ô Diên, Thành phố Hà Nội, Việt Nam
A21: Điện thoại: | C21: 02433250143
A22: Tài khoản ngân hàng số: | C22: ='Giá trị'!$C$22 -> 8331100096008 | E22: ='Giá trị'!E22:K22 -> Tại Ngân hàng Thương mại cổ phần Quân đội - Chi nhánh Hoàng Quốc Việt
A23: Mã số thuế: | C23: 0105204346
A24: Người đại diện: | C24: Ông Hữu Minh Tiến | E24: Chức vụ: Phó Tổng giám đốc
A26: Hai bên đối chiếu xác nhận khối lượng thuê thiết bị từ ngày 20/12/2025 đến ngày 25/12/2025 như sau:
A27: STT | B27: Tên thiết bị | C27: Đơn vị tính | D27: Ngày nhận/trả trên phiếu | E27: Ngày tính thời gian | F27: Số lượng tồn đầu kỳ | G27: Số lượng phát sinh trong kỳ nhận (+) trả (-) | H27: Thời gian thuê thực tế | I27: Ghi chú
A28: =ROMAN(1,0) -> I | B28: Thiết bị vật tư
A29: 1 | B29: Giáo ringlock 1.0m Kẽm | C29: Cây | D29: 46015 | E29: 46016 | G29: 1300 | H29: =E29-D29+1 -> 2
B30: Giáo ringlock 1.0m Kẽm | C30: Cây | D30: 46016 | E30: 46016 | G30: 1600 | H30: =E30-D30+1 -> 1
B31: Giáo ringlock 1.0m Kẽm | C31: Cây | D31: 46016 | E31: 46016 | G31: 1600 | H31: =E31-D31+1 -> 1
B32: Cộng | G32: =SUM(G29:G31) -> 4500
A33: 2 | B33: Giáo ringlock 1.5m Kẽm | C33: Cây | D33: 46011 | E33: 46016 | G33: 700 | H33: =E33-D33+1 -> 6
B34: Giáo ringlock 1.5m Kẽm | C34: Cây | D34: 46016 | E34: 46016 | G34: 1600 | H34: =E34-D34+1 -> 1
B35: Giáo ringlock 1.5m Kẽm | C35: Cây | D35: 46016 | E35: 46016 | G35: 1600 | H35: =E35-D35+1 -> 1
B36: Cộng | G36: =SUM(G33:G35) -> 3900
A37: 3 | B37: Giáo ringlock 2.0m Kẽm | C37: Cây | D37: 46011 | E37: 46016 | G37: 700 | H37: =E37-D37+1 -> 6
B38: Giáo ringlock 2.0m Kẽm | C38: Cây | D38: 46015 | E38: 46016 | G38: 400 | H38: =E38-D38+1 -> 2
B39: Cộng | G39: =SUM(G37:G38) -> 1100
A40: 4 | B40: Giáo ringlock 2.5m Kẽm | C40: Cây | D40: 46012 | E40: 46016 | G40: 1000 | H40: =E40-D40+1 -> 5
B41: Giáo ringlock 2.5m Kẽm | C41: Cây | D41: 46013 | E41: 46016 | G41: 2200 | H41: =E41-D41+1 -> 4
B42: Giáo ringlock 2.5m Kẽm | C42: Cây | D42: 46013 | E42: 46016 | G42: 1100 | H42: =E42-D42+1 -> 4
B43: Giáo ringlock 2.5m Kẽm | C43: Cây | D43: 46013 | E43: 46016 | G43: 2200 | H43: =E43-D43+1 -> 4
B44: Giáo ringlock 2.5m Kẽm | C44: Cây | D44: 46014 | E44: 46016 | G44: 1400 | H44: =E44-D44+1 -> 3
...

Sheet Vận chuyển
A1: CỘNG HÒA XÃ HỘI CHỦ NGHĨA VIỆT NAM
A2: Độc lập - Tự do - Hạnh phúc
A4: BẢNG THEO DÕI VẬN CHUYỂN
A6: - Căn cứ Hợp đồng nguyên tác số 1010/HĐKT2024/TP-MINHTRUONG ký ngày 10/10/2024 giữa Công ty Cổ phần Cơ khí và Xây dựng Minh Trường và Công ty Cổ phần Tập đoàn Thiết bị xây dựng TP về việc cho thuê thiết bị xây dựng.
A7: - Dự án: | B7: - Dự án: | C7: Nhà xưởng Nam Tài
A8: - Địa chỉ: | B8: - Địa chỉ: | C8: Lô B2, KCN Liên Hà Thái, Thái Thụy, Thái Bình
A9: - Căn cứ tình hình giao nhận thực tế giữa 02 bên. | B9: - Căn cứ tình hình giao nhận thực tế giữa 02 bên.
A10: Hôm nay, ngày ……tháng……năm 2024, chúng tôi gồm: | B10: Hôm nay, ngày ……tháng……năm 2024, chúng tôi gồm:
A11: BÊN THUÊ (BÊN A): CÔNG TY CỔ PHẦN CƠ KHÍ VÀ XÂY DỰNG MINH TRƯỜNG | B11: BÊN THUÊ (BÊN A): CÔNG TY CỔ PHẦN CƠ KHÍ VÀ XÂY DỰNG MINH TRƯỜNG
A12: Địa chỉ: Số 10 Lô BD2, khu đô thị PG, Xã An Đồng, Huyện An Dương, TP Hải Phòng, Việt Nam | B12: Địa chỉ: Số 10 Lô BD2, khu đô thị PG, Xã An Đồng, Huyện An Dương, TP Hải Phòng, Việt Nam
A13: Điện thoại: | B13: Điện thoại: | D13: 0225 629 4566
A14: Tài khoản ngân hàng số: | B14: Tài khoản ngân hàng số: | D14: 190366962980
A15: Mã số thuế: | B15: Mã số thuế: | D15: 0201803832
A16: Người đại diện: | B16: Người đại diện: | D16: Ông Nguyễn Văn Hùng
A18: BÊN CHO THUÊ (BÊN B): CÔNG TY CỔ PHẦN TẬP ĐOÀN THIẾT BỊ XÂY DỰNG TP | B18: BÊN CHO THUÊ (BÊN B): CÔNG TY CỔ PHẦN TẬP ĐOÀN THIẾT BỊ XÂY DỰNG TP
A19: Địa chỉ: Thôn Trung, xã Liên Trung, huyện Đan Phượng, Thành phố Hà Nội, Việt Nam | B19: Địa chỉ: Thôn Trung, xã Liên Trung, huyện Đan Phượng, Thành phố Hà Nội, Việt Nam
A20: Điện thoại: | B20: Điện thoại: | D20: 02433250143
A21: Tài khoản ngân hàng số: | B21: Tài khoản ngân hàng số: | D21: 8331100096008
A23: Mã số thuế: | B23: Mã số thuế: | D23: 0105204346
A24: Người đại diện: | B24: Người đại diện: | D24: Bà Đỗ Thị Hường
A26: STT | B26: Ngày | C26: Nội dung | D26: Loại xe | E26: Biển số xe | F26: Ghi chú
A27: Từ 11/10/2024 đến 25/10/2024
A28: 1 | B28: 45576 | C28: Giao hàng công trình | D28: Sơ mi 30 tấn | E28: 15H-064.54 | F28: Xe TP
A29: 2 | B29: 45576 | C29: Giao hàng công trình | D29: Sơ mi 30 tấn | E29: 14H-023.02 | F29: Xe TP
A30: 3 | B30: 45577 | C30: Giao hàng công trình | D30: Sơ mi 30 tấn | E30: 15H-092.86 | F30: Xe Minh Trường
A31: 4 | B31: 45577 | C31: Giao hàng công trình | D31: Cẩu 15 tấn | E31: 29K-046.43 | F31: Xe TP
A32: 5 | B32: 45579 | C32: Giao hàng công trình | D32: Sơ mi 30 tấn | E32: 15C-146.66 | F32: Xe TP
A33: 6 | B33: 45579 | C33: Giao hàng công trình | D33: Sơ mi 30 tấn | E33: 29C-482.69 | F33: Xe TP
A34: 7 | B34: 45579 | C34: Giao hàng công trình | D34: Sơ mi 30 tấn | E34: 15H-008.81 | F34: Xe TP
A35: 8 | B35: 45580 | C35: Giao hàng công trình | D35: Sơ mi 30 tấn | E35: 29H-888.96 | F35: Xe TP
A36: 9 | B36: 45580 | C36: Giao hàng công trình | D36: Sơ mi 30 tấn | E36: 15E-017.65 | F36: Xe TP
A37: 10 | B37: 45582 | C37: Giao hàng công trình | D37: Sơ mi 30 tấn | E37: 29C-070.91 | F37: Xe TP
A38: Từ 26/10/2024 đến 25/11/2024
A39: 1 | B39: 45592 | C39: Giao hàng công trình | D39: Cẩu 15 tấn | E39: 29H-720.49 | F39: Xe TP
A40: 2 | B40: 45597 | C40: Giao hàng công trình | D40: Sơ mi 30 tấn | E40: 29H-888.96 | F40: Xe TP
A41: 3 | B41: 45597 | C41: Giao hàng công trình | D41: Sơ mi 30 tấn | E41: 29H-782.22 | F41: Xe TP
A42: 4 | B42: 45600 | C42: Giao hàng công trình | D42: Cẩu 15 tấn | E42: 29H-672.55 | F42: Xe TP
A43: 5 | B43: 45605 | C43: Giao hàng công trình | D43: Sơ mi 30 tấn | E43: 15H-067.03 | F43: Xe TP
A44: 6 | B44: 45605 | C44: Giao hàng công trình | D44: Sơ mi 30 tấn | E44: 15E-017.65 | F44: Xe TP
A45: 7 | B45: 45607 | C45: Giao hàng công trình | D45: Sơ mi 30 tấn | E45: 29C-070.91 | F45: Xe TP
...
